Workbook

Sheet 1
A1: Предприятие выпускает два вида изделий: валы и зубчатые колеса. При изготовлении каждого изделия необходима обработка на трех станках: токарном, фрезерном и сверлильном. Токарный станок может использоваться не более 10 часов в сутки, фрезерный - не более 8, сверлильный - не более 10 часов. Прибыль от продажи одного вала составляет 4 ден.ед., от одного зубчатого колеса - 5 ден.ед. Затраты времени на выпуск изделий на каждом из станков приведены в таблице.
A12: Станки | B12: Затраты времени на выпуск одного изделия, мин | E12: Станки | F12: Время исп., не более мин в сутки | H12: Вид изделия | I12: Прибыль, ден.ед.
B13: Вал | C13: Зубчатое колесо
A14: Токарный | B14: 12 | C14: 5 | E14: Токарный | F14: 600 | H14: Вал | I14: 4
A15: Фрезерный | B15: 6 | C15: 11 | E15: Фрезерный | F15: 480 | H15: Зубчатое колесо | I15: 5
A16: Сверлильный | B16: 10 | C16: 10 | E16: Сверлильный | F16: 600
A18: X1 | B18: Вал
A19: X2 | B19: Зубчатое колесо | F19: X2
A21: Математическая модель
A22: Токарный | B22: 12*X1+5*X2<=600 | C22: Ограничения
A23: Фрезерный | B23: 6*X1+11*X2<=480
A24: Сверлильный | B24: 10*X1+10*X2<=600
B25: X1>=0
B26: X2>=0
A27: E= | B27: 4X1+5X2->max | C27: Целевая функция
A30: E(E)= | B30: =$I$14*0+$I$15*0 -> 0 | N30: Таким образом, точка В является оптимальным решением задачи: ни в одной из смежных с ней угловых точек ОДР (т.е. в точках А и С) значение це- левой функции по сравнению с точкой В не улучшается. Оптимальные значе- ния переменных (координаты точки В) следующие: X1=36, Х2=24. Это означает, что требуется выпускать за смену 4 корпуса и 24 задвижки. Прибыль при этом составит Е(В) = 4*36+5*24 = 264 ден. ед.
A31: E(A)= | B31: =$I$14*0+$I$15*43.63636 -> 218.1818
A32: E(B)= | B32: =$I$14*36+$I$15*24 -> 264
A33: E(C)= | B33: =$I$14*42.85714+$I$15*17.14286 -> 257.14286
A34: E(D)= | B34: =$I$14*50+$I$15*0 -> 200 | L34: X1
A38: Симплекс-метод
A40: Стандартная форма математической модели
A41: Токарный | B41: 12*X1+5*X2+X3= | C41: 600
A42: Фрезерный | B42: 6*X1+11*X2+X4= | C42: 480
A43: Сверлильный | B43: 10*X1+10*X2+X5= | C43: 600
B44: >=0; j=1,…,5
A45: E= | B45: 4X1+5X2->max
A47: Базисные переменные | D47: Не базисные переменные
A48: X3= | B48: 600 | D48: X1= | E48: 0
A49: X4= | B49: 480 | D49: X2= | E49: 0
A50: X5= | B50: 600
A53: Базис | B53: Х1 | C53: Х2 | D53: Х3 | E53: Х4 | F53: Х5 | G53: Решение | I53: Это решение является допустимым, так как значения X1=X2=0 соответствуют системе ограничений. Таким образом, в качестве начальной угловой точки ОДР выбрано начало координат. Выбранное решение явно не является оптимальным, так как целевая функция Е = 4Х1+5Х2 при этом равна нулю. По своему смыслу это решение означает, что никакие изделия не выпускаются.
A54: Е | B54: -4 | C54: -5 | D54: 0 | E54: 0 | F54: 0 | G54: 0
A55: Х3 | B55: 12 | C55: 5 | D55: 1 | E55: 0 | F55: 0 | G55: 600
A56: Х4 | B56: 6 | C56: 11 | D56: 0 | E56: 1 | F56: 0 | G56: 480
A57: Х5 | B57: 10 | C57: 10 | D57: 0 | E57: 0 | F57: 1 | G57: 600
B59: Симплексные отношения | F59: x1=0
B60: Х3: 600/5= | C60: =G55/C55 -> 120 | F60: x2=0
B61: Х4: 480/11= | C61: =G56/C56 -> 43.636364 | D61: (минимальное) | F61: x3=600
B62: Х5: 600/10= | C62: =G57/C57 -> 60 | F62: x4=480
...

Sheet 2
A1: Вид продукции, тонн | B1: Цена, тыс.д.е. | C1: Руда, тонн | D1: Опасные отходы | E1: Выпуск | F1: Доп условие
A2: Серная кислота | B2: 3 | C2: 12.5 | D2: 100 | E2: ≥200 | F2: 1
A3: Хлорпикриновая кислота | B3: 4 | C3: 6 | D3: 250 | F3: 2
B4: ≥1500 | C4: ≤5000
A7: Двухэтапный метод
A9: Серная кислота | B9: Х1 | D9: Математическая модель | G9: Стандартная форма
A10: Хлорпикриновая кислота | B10: Х2 | D10: Х1≥200 | G10: Х1-Х3=200
D11: 3Х1+4Х2≥1500 | G11: 3Х1+4Х2-Х4=1500
D12: 12,5*Х1+6*X2≤5000 | G12: 12,5*Х1+6*X2+X5=5000
D13: E=100*Х1+250*Х2->min | G13: Хi≥0, i=1,…,5
G14: -E=-100*Х1-250*Х2->max
A16: Первый этап (поиск допустимого решения)
A18: Х1-Х3+Х6=200 | D18: X6=200-X1+X3
A19: 3Х1+4Х2-Х4+Х7=1500 | D19: X7=1500-3X1-4X2+X4
A20: 12,5Х1+6X2+X5=5000 | D20: W=200-X1+X3+1500-3X1-4X2+X4->min
A21: Хi≥0, i=1,…,7 | D21: -W=-1700+4X1+4X2-X3-X4->max
A22: -E=-100*Х1-250*Х2->max
A23: W=Х6+Х7->min
A25: Полная математическая модель | E25: Базисные переменные | H25: Небазисные переменные
A26: Х1-Х3+Х6=200 | E26: Х5 | F26: 5000 | H26: Х1 | I26: 0
A27: 3Х1+4Х2-Х4+Х7=1500 | E27: Х6 | F27: 200 | H27: Х2 | I27: 0
A28: 12,5Х1+6X2+X5=5000 | E28: Х7 | F28: 1500 | H28: Х3 | I28: 0
A29: Хi≥0, i=1,…,7 | H29: Х4 | I29: 0
A30: -E=-100*Х1-250*Х2->max
A31: -W=4X1+4X2-X3-X4-1700->max
A33: Начальное значение целевой функции = 0, искусственной целевой функции = -1700
A35: Исходная Симплекс-таблица
A36: Базис | B36: Х1 | C36: Х2 | D36: Х3 | E36: Х4 | F36: Х5 | G36: Х6 | H36: Х7 | I36: Решение
A37: -E | B37: 100 | C37: 250 | D37: 0 | E37: 0 | F37: 0 | G37: 0 | H37: 0 | I37: 0
A38: -W | B38: -4 | C38: -4 | D38: 1 | E38: 1 | F38: 0 | G38: 0 | H38: 0 | I38: -1700
A39: X5 | B39: 12.5 | C39: 6 | D39: 0 | E39: 0 | F39: 1 | G39: 0 | H39: 0 | I39: 5000
A40: X6 | B40: 1 | C40: 0 | D40: -1 | E40: 0 | F40: 0 | G40: 1 | H40: 0 | I40: 200
A41: X7 | B41: 3 | C41: 4 | D41: 0 | E41: -1 | F41: 0 | G41: 0 | H41: 1 | I41: 1500
A43: Симплекс отношения
A44: X5 | B44: =I39/B39 -> 400
A45: X6 | B45: =I40/B40 -> 200
A46: X7 | B46: =I41/B41 -> 500
A48: Базис | B48: Х1 | C48: Х2 | D48: Х3 | E48: Х4 | F48: Х5 | G48: Х6 | H48: Х7 | I48: Решение
A49: -E | B49: 0 | C49: =(B40*C37-B37*C40)/B40 -> 250 | D49: =(B40*D37-B37*D40)/B40 -> 100 | E49: =($B$40*E37-$B$37*E40)/$B$40 -> 0 | F49: =($B$40*F37-$B$37*F40)/$B$40 -> 0 | G49: =($B$40*G37-$B$37*G40)/$B$40 -> -100 | H49: =($B$40*H37-$B$37*H40)/$B$40 -> 0 | I49: =($B$40*I37-$B$37*I40)/$B$40 -> -20000
A50: -W | B50: 0 | C50: =(B40*C38-B38*C40)/B40 -> -4 | D50: =(B40*D38-B38*D40)/B40 -> -3 | E50: =($B$40*E38-$B$38*E40)/$B$40 -> 1 | F50: =($B$40*F38-$B$38*F40)/$B$40 -> 0 | G50: =($B$40*G38-$B$38*G40)/$B$40 -> 4 | H50: =($B$40*H38-$B$38*H40)/$B$40 -> 0 | I50: =($B$40*I38-$B$38*I40)/$B$40 -> -900
...

Sheet 3
A1: Материал | B1: Запас материала, кг | C1: Расход на одно изделие, кг
C2: И1 | D2: И2
A3: Пластмасса | B3: 120 | C3: 4 | D3: 7
A4: Алюминий | B4: 100 | C4: 6 | D4: 4
A5: Прибыль, ден.ед. | C5: 200 | D5: 300
A7: Х1 | B7: Кол-во И1
A8: Х2 | B8: Кол-во И2
A10: Математическая модель | D10: Стандартная форма | G10: Остаточные переменные Х3, Х4 обозначают, соответсвенно, неизвестный остаток пластмассы и алюминия в килограммах. Эти переменные могут принимать как целые, так и дробные значения. Таким образом, задача является частично целочисленной
A11: 4Х1+7Х2≤120 | D11: 4Х1+7Х2+Х3=120
A12: 6Х1+4Х1≤100 | D12: 6Х1+4Х1+Х4=100
A13: X1 ≥ 0,X2 ≥ 0 | D13: Xi ≥ 0, i=1,…,4
A14: Х1, Х2 ─ целые | D14: Х1, Х2 ─ целые
A15: Е=200Х1+300Х2 → max | D15: Е=200Х1+300Х2 → max
A17: 1)
B18: X1 | C18: X2
A19: Решение | B19: 8.4615385 | C19: 12.307692 | O19: 1
A20: Целевая функция | B20: 200 | C20: 300 | D20: =SUMPRODUCT(B20:C20,B19:C19) -> 5384.6154 | E20: → | F20: max | O20: 4Х1+7Х2≤120
A21: Ограничения | B21: 4 | C21: 7 | D21: =SUMPRODUCT(B21:C21,B19:C19) -> 120 | E21: ≤ | F21: 120 | O21: 6Х1+4Х1≤100
B22: 6 | C22: 4 | D22: =SUMPRODUCT(B22:C22,B19:C19) -> 100 | E22: ≤ | F22: 100 | O22: Е=200Х1+300Х2 → max
O23: X1=8,46 | P23: X2=12,31
A24: 2) | O24: E= | P24: =D20 -> 5384.6154
B25: X1 | C25: X2 | K25: 2 | S25: 3
A26: Решение | B26: 8 | C26: 12.571429 | K26: 4Х1+7Х2≤120 | S26: 4Х1+7Х2≤120
A27: Целевая функция | B27: 200 | C27: 300 | D27: =SUMPRODUCT(B27:C27,B26:C26) -> 5371.4286 | E27: → | F27: max | K27: 6Х1+4Х1≤100 | S27: 6Х1+4Х1≤100
A28: Ограничения | B28: 4 | C28: 7 | D28: =SUMPRODUCT(B28:C28,B26:C26) -> 120 | E28: ≤ | F28: 120 | K28: X1 ≤ 8 | S28: X1 ≥ 9
B29: 6 | C29: 4 | D29: =SUMPRODUCT(B29:C29,B26:C26) -> 98.285714 | E29: ≤ | F29: 100 | K29: Е=200Х1+300Х2 → max | S29: Е=200Х1+300Х2 → max
B30: 1 | C30: 0 | D30: =SUMPRODUCT(B26:C26,B30:C30) -> 8 | E30: ≤ | F30: 8 | K30: X1=8 | L30: X2=12,57 | S30: X1=9 | T30: X2=11,25
K31: E= | L31: =D27 -> 5371.4286 | S31: E= | T31: =D35 -> 5250
A32: 3)
B33: X1 | C33: X2 | I33: 4 | M33: 5 | Q33: 6 | U33: 7
A34: Решение | B34: 9 | C34: 11.5 | I34: 4Х1+7Х2≤120 | M34: 4Х1+7Х2≤120 | Q34: 4Х1+7Х2≤120 | U34: 4Х1+7Х2≤120
A35: Целевая функция | B35: 200 | C35: 300 | D35: =SUMPRODUCT(B35:C35,B34:C34) -> 5250 | E35: → | F35: max | I35: 6Х1+4Х1≤100 | M35: 6Х1+4Х1≤100 | Q35: 6Х1+4Х1≤100 | U35: 6Х1+4Х1≤100
A36: Ограничения | B36: 4 | C36: 7 | D36: =SUMPRODUCT(B36:C36,B34:C34) -> 116.5 | E36: ≤ | F36: 120 | I36: X1 ≤ 8, Х2 ≤ 12 | M36: X1 ≤ 8, Х2 ≥13 | Q36: X1 ≥ 9, Х2 ≤ 11 | U36: X1 ≥ 9, Х2 ≥ 12
B37: 6 | C37: 4 | D37: =SUMPRODUCT(B37:C37,B34:C34) -> 100 | E37: ≤ | F37: 100 | I37: Е=200Х1+300Х2 → max | M37: Е=200Х1+300Х2 → max | Q37: Е=200Х1+300Х2 → max | U37: Е=200Х1+300Х2 → max
B38: 1 | C38: 0 | D38: =SUMPRODUCT(B34:C34,B38:C38) -> 9 | E38: ≥ | F38: 9 | I38: X1=8 | J38: X2=12 | M38: X1=7,25 | N38: X2=13 | Q38: X1=9,33 | R38: X2=11 | U38: Нет решения
I39: E= | J39: =D43 -> 5200 | M39: E= | N39: =D52 -> 5350 | Q39: E= | R39: =D61 -> 5166.6667
A40: 4)
B41: X1 | C41: X2 | K41: 8 | O41: 9
A42: Решение | B42: 8 | C42: 12 | K42: 4Х1+7Х2≤120 | O42: 4Х1+7Х2≤120
A43: Целевая функция | B43: 200 | C43: 300 | D43: =SUMPRODUCT(B43:C43,B42:C42) -> 5200 | E43: → | F43: max | K43: 6Х1+4Х1≤100 | O43: 6Х1+4Х1≤100
...

Sheet 4
A1: Шахта | B1: Населенный пункт | F1: Месечная добыча, тыс. тонн | H1: Найти объемы перевозок с каждой шахты в каждый из населенных пунктов, при которых затраты на перевозки будут минимальными. Решить задачу при следующем изменении: добыча угля на шахте 3 составляет 80 тыс. тонн.
B2: 1 | C2: 2 | D2: 3 | E2: 4
A3: 1 | B3: 6 | C3: 2 | D3: 3 | E3: 5 | F3: 100
A4: 2 | B4: 1 | C4: 2 | D4: 5 | E4: 6 | F4: 150
A5: 3 | B5: 3 | C5: 10 | D5: 20 | E5: 4 | F5: 50
A6: Потребность, тыс. тонн | B6: 75 | C6: 80 | D6: 60 | E6: 85
A8: Для удовлетворения спроса всех населенных пунктов
A10: X11+X12+X13+X14=100000
A11: X21+X22+X23+X24=150000
A12: X31+X32+X33+X34=50000
A14: Ограничения по товару
A16: X11+X21+X31=75000
A17: X12+X22+X32=80000
A18: X13+X23+X33=60000
A19: X14+X24+X34=85000
A21: Xij ≥ 0, i = 1, …, 3, j = 1, …, 4
A23: Целевая функция
A24: E=6*X11+2*X12+3*X13+5*X14+1*X21+2*X22+5*X23+6*X24+3*X31+10*X32+20*X33+4*X34 -> min
A26: Метод минимального элемента
A28: Шахта | B28: Населенный пункт | I28: Шахта | J28: Населенный пункт
B29: 1 | C29: 2 | D29: 3 | E29: 4 | J29: 1 | K29: 2 | L29: 3 | M29: 4
A30: 1 | B30: 6 | C30: 2 | D30: 3 | E30: 5 | F30: 100 | I30: 1 | J30: 6 | K30: 2 | L30: 3 | M30: 5 | N30: 100
A31: 2 | B31: 1 | C31: 2 | D31: 5 | E31: 6 | F31: 150 | I31: 2 | J31: 75 1 | K31: 2 | L31: 5 | M31: 6 | N31: 150 | O31: 75
A32: 3 | B32: 3 | C32: 10 | D32: 20 | E32: 4 | F32: 50 | I32: 3 | J32: 3 | K32: 10 | L32: 20 | M32: 4 | N32: 50
B33: 75 | C33: 80 | D33: 60 | E33: 85 | J33: 75 | K33: 80 | L33: 60 | M33: 85
A37: Шахта | B37: Населенный пункт | I37: Шахта | J37: Населенный пункт
B38: 1 | C38: 2 | D38: 3 | E38: 4 | J38: 1 | K38: 2 | L38: 3 | M38: 4
A39: 1 | B39: 6 | C39: 2 | D39: 3 | E39: 5 | F39: 100 | I39: 1 | J39: 6 | K39: 5 2 | L39: 3 | M39: 5 | N39: 100 | O39: 95
A40: 2 | B40: 75 1 | C40: 75 2 | D40: 5 | E40: 6 | F40: 150 | G40: 75 | I40: 2 | J40: 75 1 | K40: 75 2 | L40: 5 | M40: 6 | N40: 150 | O40: 75
A41: 3 | B41: 3 | C41: 10 | D41: 20 | E41: 4 | F41: 50 | I41: 3 | J41: 3 | K41: 10 | L41: 20 | M41: 4 | N41: 50
B42: 75 | C42: 80 | D42: 60 | E42: 85 | J42: 75 | K42: 80 | L42: 60 | M42: 85
C43: 5 | K43: 5
A46: Шахта | B46: Населенный пункт | J46: Шахта | K46: Населенный пункт
B47: 1 | C47: 2 | D47: 3 | E47: 4 | K47: 1 | L47: 2 | M47: 3 | N47: 4
A48: 1 | B48: 6 | C48: 5 2 | D48: 60 3 | E48: 5 | F48: 100 | G48: 95 | H48: 35 | J48: 1 | K48: 6 | L48: 5 2 | M48: 60 3 | N48: 5 | O48: 100 | P48: 95 | Q48: 35
A49: 2 | B49: 75 1 | C49: 75 2 | D49: 5 | E49: 6 | F49: 150 | G49: 75 | J49: 2 | K49: 75 1 | L49: 75 2 | M49: 5 | N49: 6 | O49: 150 | P49: 75
A50: 3 | B50: 3 | C50: 10 | D50: 20 | E50: 4 | F50: 50 | J50: 3 | K50: 3 | L50: 10 | M50: 20 | N50: 50 4 | O50: 50
B51: 75 | C51: 80 | D51: 60 | E51: 85 | K51: 75 | L51: 80 | M51: 60 | N51: 85
C52: 5 | L52: 5 | N52: 35
I55: Базисные
...

Sheet 5
A1: Необходмо составить план выполнения работ так, чтобы все работы оказались выполненными, каждый рабочий был загружен только на одной работе, а суммарная стоимость выполнения всех работ была минимальной.
A6: Работы | B6: Стоимость выполнения работ, д.е.
B7: 1 рабочий | C7: 2 рабочий | D7: 3 рабочий | E7: 4 рабочий | F7: 5 рабочий
A8: 1 | B8: 3 | C8: 6 | D8: 2 | E8: 5 | F8: 11
A9: 2 | B9: 1 | C9: 2 | D9: 7 | E9: 11 | F9: 3
A10: 3 | B10: 5 | C10: 12 | D10: 11 | E10: 9 | F10: 1
A11: 4 | B11: 2 | C11: 4 | D11: 2 | E11: 10 | F11: 5
A13: Сбалансируем задачу
A15: Работы | B15: Стоимость выполнения работ, д.е.
B16: 1 рабочий | C16: 2 рабочий | D16: 3 рабочий | E16: 4 рабочий | F16: 5 рабочий
A17: 1 | B17: 3 | C17: 6 | D17: 2 | E17: 5 | F17: 11
A18: 2 | B18: 1 | C18: 2 | D18: 7 | E18: 11 | F18: 3
A19: 3 | B19: 5 | C19: 12 | D19: 11 | E19: 9 | F19: 1
A20: 4 | B20: 2 | C20: 4 | D20: 2 | E20: 10 | F20: 5
A21: 5 | B21: 0 | C21: 0 | D21: 0 | E21: 0 | F21: 0
A24: Математическая модель
A25: Чтобы все работы оказались выполненными | E25: Чтобы каждый рабочий был загружен только на одной работе
A26: Х11+Х12+Х13+Х14+Х15=1 | E26: Х11+Х21+Х31+Х41+Х51=1
A27: Х21+Х22+Х23+Х24+Х25=1 | E27: Х12+Х22+Х32+Х42+Х52=1
A28: Х31+Х32+Х33+Х34+Х35=1 | E28: Х13+Х23+Х33+Х43+Х53=1
A29: Х41+Х42+Х43+Х44+Х45=1 | E29: Х14+Х24+Х34+Х44+Х54=1
A30: Х51+Х52+Х53+Х54+Х55=1 | E30: Х15+Х25+Х35+Х45+Х55=1
A32: Целевая функция
A33: E = 3*X11 + X12 + 5*X13 + 2*X14 + 6*X21 + 2*X22 + 12*X23 + 4*X24 + 2*X31 + 7*X32 + 11*X33 + 2*X34 + 5*Х41 + 11*Х22 + 9*Х43 + 10*Х44 + 11*Х51 + 3*Х52 + 1*Х53 + 5*Х54-> min
E38: А
A39: 3 | B39: 1 | C39: 5 | D39: 2 | E39: 0 | F39: 1
A40: 6 | B40: 2 | C40: 12 | D40: 4 | E40: 0 | F40: 2
A41: 2 | B41: 7 | C41: 11 | D41: 2 | E41: 0 | F41: 2
A42: 5 | B42: 11 | C42: 9 | D42: 10 | E42: 0 | F42: 5
A43: 11 | B43: 3 | C43: 1 | D43: 5 | E43: 0 | F43: 1 | G43: dmin
A45: 3 | B45: 1 | C45: 5 | D45: 2 | E45: 1
A46: 6 | B46: 2 | C46: 12 | D46: 4 | E46: 1
A47: 2 | B47: 7 | C47: 11 | D47: 2 | E47: 1
A48: 5 | B48: 11 | C48: 9 | D48: 10 | E48: 1
A49: 11 | B49: 3 | C49: 1' | D49: 5 | E49: 1
A51: 3 | B51: 1 | C51: 5 | D51: 2 | E51: 1 | F51: 0 | G51: dmin
A52: 6 | B52: 2 | C52: 12 | D52: 4 | E52: 1 | F52: 1
A53: 2 | B53: 7 | C53: 11 | D53: 2 | E53: 1 | F53: 1
A54: 5 | B54: 11 | C54: 9 | D54: 10 | E54: 1 | F54: 4
A55: 11 | B55: 3 | C55: 1 | D55: 5 | E55: 1
...

Sheet 6
B24: Р1 | C24: Р2
A25: Мин объем выпуска (тонн) | B25: 100 | C25: 120
A26: Прибыль от 1 тонны (тыс.ден.ед.) | B26: 2 | C26: 4
A27: Общая прибыль (млн ден. ед) | B27: 1.5
A30: Мат модель
A31: X1>=100
A32: X2>=120
A33: 2X1+4X2>=1500
A34: E=10X1+6X2+0,1X1^2+0,1X2^2->min
B37: (10+0,2*X1, 6+0,2*X2)
A41: Начальное допустимое решение
A42: 10X1+6X2->min
A43: X1>=100
A44: X2>=120 | C44: E(0)= | D44: =10*100+325*6+0.1*100*100+0.1*325*325 -> 14512.5
A45: 2X1+4X2>=1500 | C45: Точность(e) = | D45: 0.5
A47: Итерация 1
A49: Градиент Е в точке ОДР
A50: grad E(X(0))=(10+0,2*100, 6+0,2*325)=(30, 71)
A52: Угловая точка ОДР
A53: 30X1+71X2->min
A54: X1>=100
A55: X2>=120 | B55: Вывод: | C55: Поиск нового решения от т. X(0)=(100;325) к X*=(510;120)
A56: 2X1+4X2>=1500
A58: Уравнения для перехода к новому решению
A59: X1(1)=X1(0)+l(X1*-X1(0))= | B59: 100+l(510-100)
A60: X2(1)=X2(0)+l(X2*-X2(0))= | B60: 325+l(120-325)
A63: Коэффициент лямбда
A64: E=10*(100+410l)+6*(325-205l)+0,1*(100+410l)*(100+410l)+0,1*(325-205l)*(325-205l) | G64: =14512,5-2255l+21012,5l^2
A65: dE/dl=-2255+42025l=0
A66: l=0,054
A68: X1(1)=X1(0)+l(X1*-X1(0))= | B68: 100+l(510-100)= 122,14
A69: X2(1)=X2(0)+l(X2*-X2(0))= | B69: 325+l(120-325)= 313,93
A70: Целевая функция Е(1) | B70: =10*122.14+6*313.93+0.1*122.14^2+0.1*313.93^2 -> 14452.002
A72: Условие окончания
A73: deltaE=|E(1)-E(0)|=|14452,00245-14512,5| | C73: 60.49755 | E73: deltaE>e
A75: Итерация 2
A77: Градиент Е в точке ОДР
A78: grad E(X(0))=(10+0,2*122,14, 6+0,2*313,93)=(34,428, 68,786)
A80: Угловая точка ОДР
A81: 34.428X1+68.786X2->min
...

Sheet 7
A1: Выделенные средства, млн ден.ед. | C1: Предприятие
C2: П1 | D2: П2 | E2: П3 | F2: П4
A3: 0 | C3: 0 | D3: 0 | E3: 0 | F3: 0
A4: 10 | C4: 20 | D4: 15 | E4: 25 | F4: 12
A5: 20 | C5: 22 | D5: 18 | E5: 30 | F5: 22
A6: 30 | C6: 28 | D6: 30 | E6: 32 | F6: 30
A7: 40 | C7: 40 | D7: 50 | E7: 40 | F7: 38
A8: 50 | C8: 52 | D8: 55 | E8: 46 | F8: 45
A9: 60 | C9: 60 | D9: 70 | E9: 53 | F9: 50
A11: S0=60
A12: E=Z1+Z2+Z3+Z4
A14: Шаг 4 (выделение средств предприятию П4)
A16: S3 | B16: U*4 | C16: E*4
A17: 0 | B17: 0 | C17: 0
A18: 10 | B18: 10 | C18: 12
A19: 20 | B19: 20 | C19: 22
A20: 30 | B20: 30 | C20: 30
A21: 40 | B21: 40 | C21: 38
A22: 50 | B22: 50 | C22: 45
A23: 60 | B23: 60 | C23: 50
A25: Шаг 3 (выделение средств предприятиям П3 и П4)
A27: S2 | B27: U3 | C27: Z3 | D27: S3 | E27: E*4 | F27: E3 | G27: U*3 | H27: E*3
A28: 0 | B28: 0 | C28: 0 | D28: 0 | E28: 0 | F28: 0 | G28: 0 | H28: 0
A29: 10 | B29: 0 | C29: 0 | D29: 10 | E29: 12 | F29: =0+12 -> 12 | G29: 10 | H29: 25
B30: 10 | C30: 25 | D30: 0 | E30: 0 | F30: 25
A31: 20 | B31: 0 | C31: 0 | D31: 20 | E31: 22 | F31: 22 | G31: 10 | H31: 37
B32: 10 | C32: 25 | D32: 10 | E32: 12 | F32: =C32+E32 -> 37
B33: 20 | C33: 30 | D33: 0 | E33: 0 | F33: 30
A34: 30 | B34: 0 | C34: 0 | D34: 30 | E34: 30 | F34: 30 | G34: 10 | H34: 47
B35: 10 | C35: 25 | D35: 20 | E35: 22 | F35: =E35+C35 -> 47
B36: 20 | C36: 30 | D36: 10 | E36: 12 | F36: =E36+C36 -> 42
B37: 30 | C37: 32 | D37: 0 | E37: 0 | F37: 32
A38: 40 | B38: 0 | C38: 0 | D38: 40 | E38: 38 | F38: =E38+C38 -> 38 | G38: 10 | H38: 55
B39: 10 | C39: 25 | D39: 30 | E39: 30 | F39: =E39+C39 -> 55
B40: 20 | C40: 30 | D40: 20 | E40: 22 | F40: =E40+C40 -> 52
B41: 30 | C41: 32 | D41: 10 | E41: 12 | F41: =E41+C41 -> 44
B42: 40 | C42: 40 | D42: 0 | E42: 0 | F42: =E42+C42 -> 40
A43: 50 | B43: 0 | C43: 0 | D43: 50 | E43: 45 | F43: =E43+C43 -> 45 | G43: 10 | H43: 63
B44: 10 | C44: 25 | D44: 40 | E44: 38 | F44: =E44+C44 -> 63
B45: 20 | C45: 30 | D45: 30 | E45: 30 | F45: =E45+C45 -> 60
...

Sheet 8_1
A1: На участке выпускаются детали двух видов. Заготовки для выпуска деталей поступают на участок через каждые 6±2 минуты. Все заготовки обрабатываются на станке A; время обработки детали на станке распределено по экспоненциальному закону и составляет в среднем 5 минут.
A5: 10% деталей, выпущенных на станке A, продаются как готовые изделия (детали типа1). Остальные проходят дальнейшую обработку (из них выпускаются детали типа 2). Детали типа 1 со станка A поступают на два одинаковых станка (B1 и B2); время обработки одной детали на этих станках распределено по экспоненциальному закону и составляет в среднем 12 минут. Перед станками B1 и B2 установлен общий накопитель, вмещающий пять деталей; при его заполнении все поступающие детали типа 1 направляются на станок C, на котором обработка занимает ровно 7 минут.
A13: Затраты (в денежных единицах), связанные с работой и простоями каждого станка (в минуту), приведены в таблице.
B15: A | C15: B | D15: C
A16: Работа | B16: 0.3 | C16: 0.6 | D16: 0.5
A17: Простой | B17: 0.1 | C17: 0.2 | D17: 0.1
A18: Прочие расходы, связанные с выпуском деталей типа 1 и 2, составляют 2 и 8 д.е. соответственно. Детали типа 1 продаются по цене 5 д.е., типа 2 - 22 д.е.
A20: 1. Найти характеристики работы станка A (8.4, 8.7). 2. Найти характеристики работы группы станков B1-B2 (8.13, 8.4, 8.9). Поток деталей на эту группу станков считать пуассоновским. 3. Рассчитать характеристики работы станка C (8.13, 8.4, 8.7). Поток деталей на станок C считать пуассоновскими. 4. Найти прибыль от работы участка за 8 часов (8.6, 8.7, 8.9). 5. Найти вероятность того, что деталь, поступившая на станки B1-B2, сразу же начнет обрабатываться (не будет ждать в очереди) (8.5, 8.9, пример из 8.8).
A28: 6. Найти характеристики работы всех станков и прибыль от работы участка (за 8 часов) при следующих изменениях: заготовки поступают на обработку чаще (через каждые 4±2 минуты), а станок A заменен на новый (A1); среднее время обработки одной детали на станке A1 - 3 минуты (экспоненциальная случайная величина). Для нового станка A1 затраты на одну минуту работы и простоя - 0,4 и 0,2 д.е. соответственно. Определить, яляется ли предлагаемые изменения целесообразными.

Sheet 8_2
A1: Найти характеристики работы станка A | B1: G/M/1
A3: На участке выпускаются детали двух видов. Заготовки для выпуска деталей поступают на участок через каждые 6±2 минуты. Все заготовки обрабатываются на станке A; время обработки детали на станке распределено по экспоненциальному закону и составляет в среднем 5 минут.
B7: A
A8: Работа | B8: 0.3
A9: Простой | B9: 0.1
A10: Прочие расходы, связанные с выпуском деталей типа 1 и 2, составляют 2 и 8 д.е. соответственно. Детали типа 1 продаются по цене 5 д.е., типа 2 - 22 д.е.
A13: Параметры станка А
A14: Интенсивность потока заявок, дет/мин. | B14: 𝜆 = 1/6 = | C14: =1/6 -> 0.16666667 | D14: (4+8)/2=6
A15: Количество каналов | B15: m = | C15: 1
A16: Среднее время обслуживания заявки | B16: x̅ = | C16: 5
A17: Интенвивность обсл. заявок, дет/мин. | B17: µ = 1/x̅ = | C17: =1/C16 -> 0.2
A19: Характеристики станка А
A20: Вероятность простоя, Ро | B20: 1 - ρ= | C20: =1-C30 -> 0.16666667
A21: Вероятность отказа, Ротк | C21: 0
A22: Вероятность обслуживания, Робсл | C22: 1
A23: Коэф.загрузки, U | B23: ρ = | C23: =C30 -> 0.83333333
A24: Средняя длина очереди, q̅ | B24: (ρ^2*(v^2+ε^2))/ (2*(1-ρ)) = | C24: =(C30^2*(C31^2+C32^2))/(2*(1-C30)) -> 2.3148148
A25: Среднее число занятый каналов, S̅ | B25: m*U= | C25: =C15*C23 -> 0.83333333
A26: На обслуживании в очереди, k̅ | B26: q̅ + S̅ = | C26: =C24+C25 -> 3.1481481
A27: Среднее время ожидания обслучивания, w̅ | B27: q̅ / γ = | C27: =C24/C29 -> 13.888889
A28: В очереди и на обслуживании, t̅ | B28: w̅ + x̅ = | C28: =C27+C16 -> 18.888889
A29: Пропускная способность, γ | B29: 𝜆 = | C29: =C14 -> 0.16666667
A30: Нагрузка на канал, ρ | B30: 𝜆 / (m*µ)= | C30: =C14/(C15*C17) -> 0.83333333
A31: Коэфф вариации интервалов времени между заявками, v | B31: σ/x̅ = | C31: =2/6 -> 0.33333333
A32: Коэфф вариации времени обслуживания, ε | C32: 1

Sheet 8_3
A1: Перед станками B1 и B2 установлен общий накопитель, вмещающий пять деталей; при его заполнении все поступающие детали типа 1 направляются на станок C, на котором обработка занимает ровно 7 минут.
A4: M/D/1
A6: Параметры станков C
A7: Интенсивность потока заявок, дет/мин | B7: P𝜆 = | C7: ='8_4'!C10*'8_4'!C17 -> 0.013809433
A8: Количество каналов | B8: m = | C8: 1
A9: Среднее время обслуживания заявки | B9: x̅ = | C9: 7
A10: Интенвивность обсл. заявок, дет/мин | B10: µ = 1/x̅ = | C10: =1/C9 -> 0.14285714
A12: Характеристики станков C
A13: Вероятность простоя, Ро | B13: 1 - ρ = | C13: =1-C23 -> 0.90333397
A14: Вероятность отказа, Ротк | C14: 0
A15: Вероятность обслуживания, Робсл | B15: 1-Ротк= | C15: =1-C14 -> 1
A16: Коэф.загрузки, U | B16: ρ = | C16: =C23*C15 -> 0.096666034
A17: Средняя длина очереди, q̅ | B17: (ρ^2*(v^2+ε^2))/ (2*(1-ρ))= | C17: =(C23^2*(C24^2+C25^2))/(2*(1-C23)) -> 0.0051721304
A18: Среднее число занятый каналов, S̅ | B18: m*U= | C18: =C8*C16 -> 0.096666034
A19: На обслуживании в очереди, k̅ | B19: q̅ + S̅ = | C19: =C17+C18 -> 0.10183816
A20: Среднее время ожидания обслучивания, w̅ | B20: q̅ / γ = | C20: =C17/C22 -> 0.37453603
A21: В очереди и на обслуживании, t̅ | B21: w̅ + x̅ = | C21: =C20+C9 -> 7.374536
A22: Пропускная способность, γ | B22: 𝜆 = | C22: =C7 -> 0.013809433
A23: Нагрузка на канал, ρ | B23: 𝜆 / (m*µ)= | C23: =C7/(C8*C10) -> 0.096666034 | D23: <1
A24: Коэфф вариации интервалов времени между заявками, v | C24: 1
A25: Коэфф вариации времени обслуживания, ε | C25: 0

Sheet 8_4
A1: Найти характеристики работы группы станков B1-B2 (8.13, 8.4, 8.9). Поток деталей на эту группу станков считать пуассоновским.
A4: Детали типа 1 со станка A поступают на два одинаковых станка (B1 и B2);
A5: Время обработки одной детали на этих станках распределено по экспоненциальному закону и составляет в среднем 12 минут. Перед станками B1 и B2 установлен общий накопитель, вмещающий пять деталей;
A8: М/M/2
A9: Параметры станков В1-В2
A10: Интенсивность потока заявок, дет/мин | B10: 𝜆 = 0,9*(1/6 )= | C10: =(1/6)*0.9 -> 0.15
A11: Количество каналов | B11: m = | C11: 2
A12: Среднее время обслуживания заявки | B12: x̅ = | C12: 12
A13: Интенвивность обсл. заявок, дет/мин | B13: µ = 1/x̅ = | C13: =1/C12 -> 0.083333333
A15: Характеристики станков В1-В2
A16: Вероятность простоя, Ро | C16: =((221/50)+(29853279/5000000))^(-1) -> 0.096240316
A17: Вероятность отказа, Ротк | B17: (mρ)^(m+n)/(m^n⋅m!) *P0 = | C17: =((C11*C26)^7/(2^5*2))*C16 -> 0.09206289
A18: Вероятность обслуживания, Робсл | B18: 1-Ротк= | C18: =1-C17 -> 0.90793711
A19: Коэф.загрузки, U | B19: ρ * (1-Ротк) = | C19: =C26*C18 -> 0.8171434
A20: Средняя длина очереди, q̅ | B20: ((mρ)^(m+1)∗P_0)/(m⋅m!)∗(1-(n+1) ρ^n+nρ^(n+1))/(1-ρ)^2 = | C20: =(((C26*2)^(2+1)*C16)/(2*2))*((1-6*C26^5+5*C26^6)/((1-C26)^2)) -> 1.603348
A21: Среднее число занятый каналов, S̅ | B21: m*U= | C21: =C11*C19 -> 1.6342868
A22: На обслуживании в очереди, k̅ | B22: q̅ + S̅ = | C22: =C20+C21 -> 3.2376348
A23: Среднее время ожидания обслучивания, w̅ | B23: q̅ / γ = | C23: =C20/C25 -> 11.772827
A24: В очереди и на обслуживании, t̅ | B24: w̅ + x̅ = | C24: =C23+C12 -> 23.772827
A25: Пропускная способность, γ | B25: µ * S̅ = | C25: =C13*C21 -> 0.13619057
A26: Нагрузка на канал, ρ | B26: 𝜆 / (m*µ)= | C26: =C10/(C11*C13) -> 0.9 | D26: <1
A27: 5.Вероятность отсутствия очереди, Р(j≤1) | B27: P0+P(1)=P0+(mρ)^(m−1)/((m−1)!) P0 = | C27: =C16+(C11*C26)*C16 -> 0.26947289

Sheet 8_5
A1: Найти характеристики работы станка A1 | B1: G/M/1
A3: заготовки поступают на обработку чаще (через каждые 4±2 минуты), а станок A заменен на новый (A1); среднее время обработки одной детали на станке A1 - 3 минуты (экспоненциальная случайная величина).
B7: A1
A8: Работа | B8: 0.4
A9: Простой | B9: 0.2
A13: Параметры станка А
A14: Интенсивность потока заявок, дет/мин. | B14: 𝜆 = 1/4 = | C14: =1/4 -> 0.25 | D14: (2+6)/2=4
A15: Количество каналов | B15: m = | C15: 1
A16: Среднее время обслуживания заявки | B16: x̅ = | C16: 3
A17: Интенвивность обсл. заявок, дет/мин. | B17: µ = 1/x̅ = | C17: =1/C16 -> 0.33333333
A19: Характеристики станка А
A20: Вероятность простоя, Ро | B20: 1 - ρ= | C20: =1-C30 -> 0.25
A21: Вероятность отказа, Ротк | C21: 0
A22: Вероятность обслуживания, Робсл | C22: 1
A23: Коэф.загрузки, U | B23: ρ = | C23: =C30 -> 0.75
A24: Средняя длина очереди, q̅ | B24: (ρ^2*(v^2+ε^2))/ (2*(1-ρ)) = | C24: =(C30^2*(C31^2+C32^2))/(2*(1-C30)) -> 1.40625
A25: Среднее число занятый каналов, S̅ | B25: m*U= | C25: =C15*C23 -> 0.75
A26: На обслуживании в очереди, k̅ | B26: q̅ + S̅ = | C26: =C24+C25 -> 2.15625
A27: Среднее время ожидания обслучивания, w̅ | B27: q̅ / γ = | C27: =C24/C29 -> 5.625
A28: В очереди и на обслуживании, t̅ | B28: w̅ + x̅ = | C28: =C27+C16 -> 8.625
A29: Пропускная способность, γ | B29: 𝜆 = | C29: =C14 -> 0.25
A30: Нагрузка на канал, ρ | B30: 𝜆 / (m*µ)= | C30: =C14/(C15*C17) -> 0.75
A31: Коэфф вариации интервалов времени между заявками, v | B31: σ/x̅ = | C31: =2/4 -> 0.5
A32: Коэфф вариации времени обслуживания, ε | C32: 1

Sheet 8_6
A1: Найти характеристики работы группы станков B1-B2 (8.13, 8.4, 8.9). Поток деталей на эту группу станков считать пуассоновским.
A4: Детали типа 1 со станка A поступают на два одинаковых станка (B1 и B2);
A5: Время обработки одной детали на этих станках распределено по экспоненциальному закону и составляет в среднем 12 минут. Перед станками B1 и B2 установлен общий накопитель, вмещающий пять деталей;
A9: Параметры станков В1-В2
A10: Интенсивность потока заявок, дет/мин | B10: 𝜆 = 0,9*(1/4 )= | C10: =(1/4)*0.9 -> 0.225
A11: Количество каналов | B11: m = | C11: 2
A12: Среднее время обслуживания заявки | B12: x̅ = | C12: 12
A13: Интенвивность обсл. заявок, дет/мин | B13: µ = 1/x̅ = | C13: =1/C12 -> 0.083333333
A15: Характеристики станков В1-В2
A16: Вероятность простоя, Ро | C16: =((1469/200)+(27^8-19683*20^5)/(28000*20^4))^(-1) -> 0.017753153
A17: Вероятность отказа, Ротк | B17: (mρ)^(m+n)/(m^n⋅m!) *P0 = | C17: =((C11*C26)^7/(2^5*2))*C16 -> 0.2901629
A18: Вероятность обслуживания, Робсл | B18: 1-Ротк= | C18: =1-C17 -> 0.7098371
A19: Коэф.загрузки, U | B19: ρ * (1-Ротк) = | C19: =C26*C18 -> 0.95828009 | D19: >0,85
A20: Средняя длина очереди, q̅ | B20: ((mρ)^(m+1)∗P_0)/(m⋅m!)∗(1-(n+1) ρ^n+nρ^(n+1))/(1-ρ)^2 = | C20: =(((C26*2)^(2+1)*C16)/(2*2))*((1-6*C26^5+5*C26^6)/((1-C26)^2)) -> 3.1114185
A21: Среднее число занятый каналов, S̅ | B21: m*U= | C21: =C11*C19 -> 1.9165602
A22: На обслуживании в очереди, k̅ | B22: q̅ + S̅ = | C22: =C20+C21 -> 5.0279786
A23: Среднее время ожидания обслучивания, w̅ | B23: q̅ / γ = | C23: =C20/C25 -> 19.481268
A24: В очереди и на обслуживании, t̅ | B24: w̅ + x̅ = | C24: =C23+C12 -> 31.481268
A25: Пропускная способность, γ | B25: µ * S̅ = | C25: =C13*C21 -> 0.15971335
A26: Нагрузка на канал, ρ | B26: 𝜆 / (m*µ)= | C26: =C10/(C11*C13) -> 1.35 | D26: >1
A27: 5.Вероятность отсутствия очереди, Р(j≤1) | B27: P0+P(1)=P0+(mρ)^(m−1)/((m−1)!) P0 = | C27: =C16+(C11*C26)*C16 -> 0.065686667

Sheet 8_7
A1: Перед станками B1 и B2 установлен общий накопитель, вмещающий пять деталей; при его заполнении все поступающие детали типа 1 направляются на станок C, на котором обработка занимает ровно 7 минут.
A6: Параметры станков C
A7: Интенсивность потока заявок, дет/мин | B7: P𝜆 = | C7: ='8_6'!C10*'8_6'!C17 -> 0.065286652
A8: Количество каналов | B8: m = | C8: 1
A9: Среднее время обслуживания заявки | B9: x̅ = | C9: 7
A10: Интенвивность обсл. заявок, дет/мин | B10: µ = 1/x̅ = | C10: =1/C9 -> 0.14285714
A12: Характеристики станков C
A13: Вероятность простоя, Ро | B13: 1 - ρ = | C13: =1-C23 -> 0.54299344
A14: Вероятность отказа, Ротк | C14: 0
A15: Вероятность обслуживания, Робсл | B15: 1-Ротк= | C15: =1-C14 -> 1
A16: Коэф.загрузки, U | B16: ρ = | C16: =C23*C15 -> 0.45700656 | D16: <0,75
A17: Средняя длина очереди, q̅ | B17: (ρ^2*(v^2+ε^2))/ (2*(1-ρ))= | C17: =(C23^2*(C24^2+C25^2))/(2*(1-C23)) -> 0.19231816
A18: Среднее число занятый каналов, S̅ | B18: m*U= | C18: =C8*C16 -> 0.45700656
A19: На обслуживании в очереди, k̅ | B19: q̅ + S̅ = | C19: =C17+C18 -> 0.64932472
A20: Среднее время ожидания обслучивания, w̅ | B20: q̅ / γ = | C20: =C17/C22 -> 2.9457501
A21: В очереди и на обслуживании, t̅ | B21: w̅ + x̅ = | C21: =C20+C9 -> 9.9457501
A22: Пропускная способность, γ | B22: 𝜆 = | C22: =C7 -> 0.065286652
A23: Нагрузка на канал, ρ | B23: 𝜆 / (m*µ)= | C23: =C7/(C8*C10) -> 0.45700656 | D23: <1
A24: Коэфф вариации интервалов времени между заявками, v | C24: 1
A25: Коэфф вариации времени обслуживания, ε | C25: 0

Sheet 8_8
A1: Найти прибыль от работы участка за 8 часов (8.6, 8.7, 8.9)
A3: Выручка от обслуживания заявок в течении времени Т:
A4: V = γ*C*T=V(A)+V(B1-B2)+V(C)= | E4: =B15*B16*480+C15*C16*480+D15*D16*480 -> 2976
A5: Затраты связанные собслуживанием заявок в канале в в течение времени Т:
A6: Zобсл = γ* Cобсл* T= | E6: =B15*B17*480+C15*C17*480+D15*D17*480 -> 1104
A7: Затраты, связанные с эксплуатацией канала в течение времени T:
A8: Zэксп = ( S̅ * Cраб + (m - S̅ ) *Cпр )*T= | E8: =(B19*B11+(B20-B19)*B12)*B18+(C19*C11+(C20-C19)*C12)*B18+(D19*D11+(D20-D19)*D12)*B18 -> 863.72481
B10: A | C10: B | D10: C
A11: Работа | B11: 0.4 | C11: 0.6 | D11: 0.5
A12: Простой | B12: 0.2 | C12: 0.2 | D12: 0.1
A13: Прочие расходы, связанные с выпуском деталей типа 1 и 2, составляют 2 и 8 д.е. соответственно. Детали типа 1 продаются по цене 5 д.е., типа 2 - 22 д.е.
A15: γ | B15: ='8_5'!C29 -> 0.25 | C15: ='8_6'!C25 -> 0.15971335 | D15: ='8_7'!C22 -> 0.065286652
A16: Выручка | B16: 5 | C16: 22 | D16: 22
A17: Прочие | B17: 2 | C17: 8 | D17: 8
A18: Т, мин | B18: 480
A19: S̅ | B19: ='8_5'!C25 -> 0.75 | C19: ='8_6'!C21 -> 1.9165602 | D19: ='8_7'!C18 -> 0.45700656
A20: m | B20: 1 | C20: 2 | D20: 1
A22: Общая прибль: | C22: V - Zобсл - Zэксп = | E22: =E4-E6-E8 -> 1008.2752

Sheet 8_9
A1: Характеристики | C1: А | D1: В1-В2 | E1: С | F1: А1 | G1: В1"-В2" | H1: С"
A2: P0 | C2: ='8_2'!C20 -> 0.16666667 | D2: ='8_4'!C16 -> 0.096240316 | E2: ='8_3'!C13 -> 0.90333397 | F2: ='8_5'!C20 -> 0.25 | G2: ='8_6'!C16 -> 0.017753153 | H2: ='8_7'!C13 -> 0.54299344
A3: Pотк | C3: 0 | D3: ='8_4'!C17 -> 0.09206289 | E3: ='8_3'!C14 -> 0 | F3: ='8_5'!C21 -> 0 | G3: ='8_6'!C17 -> 0.2901629 | H3: ='8_7'!C14 -> 0
A4: Pобсл | C4: ='8_2'!C22 -> 1 | D4: ='8_4'!C18 -> 0.90793711 | E4: ='8_3'!C15 -> 1 | F4: ='8_5'!C22 -> 1 | G4: ='8_6'!C18 -> 0.7098371 | H4: ='8_7'!C15 -> 1
A5: ρ | C5: ='8_2'!C30 -> 0.83333333 | D5: ='8_4'!C26 -> 0.9 | E5: ='8_3'!C23 -> 0.096666034 | F5: ='8_5'!C30 -> 0.75 | G5: ='8_6'!C26 -> 1.35 | H5: ='8_7'!C23 -> 0.45700656
A6: U | C6: ='8_2'!C23 -> 0.83333333 | D6: ='8_4'!C19 -> 0.8171434 | E6: ='8_3'!C16 -> 0.096666034 | F6: ='8_5'!C23 -> 0.75 | G6: ='8_6'!C19 -> 0.95828009 | H6: ='8_7'!C16 -> 0.45700656
A7: S̅ , деталей | C7: ='8_2'!C25 -> 0.83333333 | D7: ='8_4'!C21 -> 1.6342868 | E7: ='8_3'!C18 -> 0.096666034 | F7: ='8_5'!C25 -> 0.75 | G7: ='8_6'!C21 -> 1.9165602 | H7: ='8_7'!C18 -> 0.45700656
A8: 𝑞̅ , деталей | C8: ='8_2'!C24 -> 2.3148148 | D8: ='8_4'!C20 -> 1.603348 | E8: ='8_3'!C17 -> 0.0051721304 | F8: ='8_5'!C24 -> 1.40625 | G8: ='8_6'!C20 -> 3.1114185 | H8: ='8_7'!C17 -> 0.19231816
A9: k, деталей | C9: ='8_2'!C26 -> 3.1481481 | D9: ='8_4'!C22 -> 3.2376348 | E9: ='8_3'!C19 -> 0.10183816 | F9: ='8_5'!C26 -> 2.15625 | G9: ='8_6'!C22 -> 5.0279786 | H9: ='8_7'!C19 -> 0.64932472
A10: 𝛾, дет/мин | C10: ='8_2'!C29 -> 0.16666667 | D10: ='8_4'!C25 -> 0.13619057 | E10: ='8_3'!C22 -> 0.013809433 | F10: ='8_5'!C29 -> 0.25 | G10: ='8_6'!C25 -> 0.15971335 | H10: ='8_7'!C22 -> 0.065286652
A11: 𝑤̅, мин | C11: ='8_2'!C27 -> 13.888889 | D11: ='8_4'!C23 -> 11.772827 | E11: ='8_3'!C20 -> 0.37453603 | F11: ='8_5'!C27 -> 5.625 | G11: ='8_6'!C23 -> 19.481268 | H11: ='8_7'!C20 -> 2.9457501
A12: 𝑡̅, мин | C12: ='8_2'!C28 -> 18.888889 | D12: ='8_4'!C24 -> 23.772827 | E12: ='8_3'!C21 -> 7.374536 | F12: ='8_5'!C28 -> 8.625 | G12: ='8_6'!C24 -> 31.481268 | H12: ='8_7'!C21 -> 9.9457501
A13: Вероятность отсутствия очереди B1-B2 | C13: ='8_4'!C27 -> 0.26947289 | F13: ='8_6'!C27 -> 0.065686667
A14: Прибыль | C14: ='8_10'!E22 -> 547.65706 | F14: ='8_8'!E22 -> 1008.2752

Sheet 8_10
A1: Найти прибыль от работы участка за 8 часов (8.6, 8.7, 8.9)
A3: Выручка от обслуживания заявок в течении времени Т:
A4: V = γ*C*T=V(A)+V(B1-B2)+V(C)= | E4: =B15*B16*480+C15*C16*480+D15*D16*480 -> 1984
A5: Затраты связанные собслуживанием заявок в канале в в течение времени Т:
A6: Zобсл = γ* Cобсл* T= | E6: =B15*B17*480+C15*C17*480+D15*D17*480 -> 736
A7: Затраты, связанные с эксплуатацией канала в течение времени T:
A8: Zэксп = ( S̅ * Cраб + (m - S̅ ) *Cпр )*T= | E8: =(B19*B11+(B20-B19)*B12)*B18+(C19*C11+(C20-C19)*C12)*B18+(D19*D11+(D20-D19)*D12)*B18 -> 700.34294
B10: A | C10: B | D10: C
A11: Работа | B11: 0.3 | C11: 0.6 | D11: 0.5
A12: Простой | B12: 0.1 | C12: 0.2 | D12: 0.1
A13: Прочие расходы, связанные с выпуском деталей типа 1 и 2, составляют 2 и 8 д.е. соответственно. Детали типа 1 продаются по цене 5 д.е., типа 2 - 22 д.е.
A15: γ | B15: ='8_2'!C29 -> 0.16666667 | C15: ='8_4'!C25 -> 0.13619057 | D15: ='8_3'!C22 -> 0.013809433
A16: Выручка | B16: 5 | C16: 22 | D16: 22
A17: Прочие | B17: 2 | C17: 8 | D17: 8
A18: Т, мин | B18: 480
A19: S̅ | B19: ='8_2'!C25 -> 0.83333333 | C19: ='8_4'!C21 -> 1.6342868 | D19: ='8_3'!C18 -> 0.096666034
A20: m | B20: 1 | C20: 2 | D20: 1
A22: Общая прибль: | C22: V - Zобсл - Zэксп = | E22: =E4-E6-E8 -> 547.65706
